[2023-05-23T10:08:49.736+0000] {taskinstance.py:1103} INFO - Dependencies all met for dep_context=non-requeueable deps ti=<TaskInstance: dag_with_taskflow_api_v02.get_name scheduled__2021-10-26T00:00:00+00:00 [queued]>
[2023-05-23T10:08:49.752+0000] {taskinstance.py:1103} INFO - Dependencies all met for dep_context=requeueable deps ti=<TaskInstance: dag_with_taskflow_api_v02.get_name scheduled__2021-10-26T00:00:00+00:00 [queued]>
[2023-05-23T10:08:49.753+0000] {taskinstance.py:1308} INFO - Starting attempt 1 of 6
[2023-05-23T10:08:49.995+0000] {taskinstance.py:1327} INFO - Executing <Task(_PythonDecoratedOperator): get_name> on 2021-10-26 00:00:00+00:00
[2023-05-23T10:08:50.065+0000] {standard_task_runner.py:57} INFO - Started process 704 to run task
[2023-05-23T10:08:50.283+0000] {standard_task_runner.py:84} INFO - Running: ['***', 'tasks', 'run', 'dag_with_taskflow_api_v02', 'get_name', 'scheduled__2021-10-26T00:00:00+00:00', '--job-id', '5', '--raw', '--subdir', 'DAGS_FOLDER/first_dag.py', '--cfg-path', '/tmp/tmp4ok0ct8g']
[2023-05-23T10:08:50.294+0000] {standard_task_runner.py:85} INFO - Job 5: Subtask get_name
[2023-05-23T10:08:50.937+0000] {task_command.py:410} INFO - Running <TaskInstance: dag_with_taskflow_api_v02.get_name scheduled__2021-10-26T00:00:00+00:00 [running]> on host fb58d5a02d2c
[2023-05-23T10:09:07.778+0000] {job.py:216} ERROR - Job heartbeat got an exception
Traceback (most recent call last):
  File "/home/airflow/.local/lib/python3.7/site-packages/sqlalchemy/engine/base.py", line 3366, in _wrap_pool_connect
    return fn()
  File "/home/airflow/.local/lib/python3.7/site-packages/sqlalchemy/pool/base.py", line 327, in connect
    return _ConnectionFairy._checkout(self)
  File "/home/airflow/.local/lib/python3.7/site-packages/sqlalchemy/pool/base.py", line 894, in _checkout
    fairy = _ConnectionRecord.checkout(pool)
  File "/home/airflow/.local/lib/python3.7/site-packages/sqlalchemy/pool/base.py", line 493, in checkout
    rec = pool._do_get()
  File "/home/airflow/.local/lib/python3.7/site-packages/sqlalchemy/pool/impl.py", line 256, in _do_get
    return self._create_connection()
  File "/home/airflow/.local/lib/python3.7/site-packages/sqlalchemy/pool/base.py", line 273, in _create_connection
    return _ConnectionRecord(self)
  File "/home/airflow/.local/lib/python3.7/site-packages/sqlalchemy/pool/base.py", line 388, in __init__
    self.__connect()
  File "/home/airflow/.local/lib/python3.7/site-packages/sqlalchemy/pool/base.py", line 691, in __connect
    pool.logger.debug("Error on connect(): %s", e)
  File "/home/airflow/.local/lib/python3.7/site-packages/sqlalchemy/util/langhelpers.py", line 72, in __exit__
    with_traceback=exc_tb,
  File "/home/airflow/.local/lib/python3.7/site-packages/sqlalchemy/util/compat.py", line 211, in raise_
    raise exception
  File "/home/airflow/.local/lib/python3.7/site-packages/sqlalchemy/pool/base.py", line 686, in __connect
    self.dbapi_connection = connection = pool._invoke_creator(self)
  File "/home/airflow/.local/lib/python3.7/site-packages/sqlalchemy/engine/create.py", line 574, in connect
    return dialect.connect(*cargs, **cparams)
  File "/home/airflow/.local/lib/python3.7/site-packages/sqlalchemy/engine/default.py", line 598, in connect
    return self.dbapi.connect(*cargs, **cparams)
  File "/home/airflow/.local/lib/python3.7/site-packages/psycopg2/__init__.py", line 122, in connect
    conn = _connect(dsn, connection_factory=connection_factory, **kwasync)
psycopg2.OperationalError: could not translate host name "postgres" to address: Temporary failure in name resolution


The above exception was the direct cause of the following exception:

Traceback (most recent call last):
  File "/home/airflow/.local/lib/python3.7/site-packages/airflow/jobs/job.py", line 187, in heartbeat
    session.merge(self)
  File "/home/airflow/.local/lib/python3.7/site-packages/sqlalchemy/orm/session.py", line 3062, in merge
    _resolve_conflict_map=_resolve_conflict_map,
  File "/home/airflow/.local/lib/python3.7/site-packages/sqlalchemy/orm/session.py", line 3140, in _merge
    options=options,
  File "/home/airflow/.local/lib/python3.7/site-packages/sqlalchemy/orm/session.py", line 2861, in get
    execution_options=execution_options,
  File "/home/airflow/.local/lib/python3.7/site-packages/sqlalchemy/orm/session.py", line 2979, in _get_impl
    load_options=load_options,
  File "/home/airflow/.local/lib/python3.7/site-packages/sqlalchemy/orm/loading.py", line 534, in load_on_pk_identity
    bind_arguments=bind_arguments,
  File "/home/airflow/.local/lib/python3.7/site-packages/sqlalchemy/orm/session.py", line 1716, in execute
    conn = self._connection_for_bind(bind)
  File "/home/airflow/.local/lib/python3.7/site-packages/sqlalchemy/orm/session.py", line 1556, in _connection_for_bind
    engine, execution_options
  File "/home/airflow/.local/lib/python3.7/site-packages/sqlalchemy/orm/session.py", line 750, in _connection_for_bind
    conn = bind.connect()
  File "/home/airflow/.local/lib/python3.7/site-packages/sqlalchemy/engine/base.py", line 3320, in connect
    return self._connection_cls(self, close_with_result=close_with_result)
  File "/home/airflow/.local/lib/python3.7/site-packages/sqlalchemy/engine/base.py", line 96, in __init__
    else engine.raw_connection()
  File "/home/airflow/.local/lib/python3.7/site-packages/sqlalchemy/engine/base.py", line 3399, in raw_connection
    return self._wrap_pool_connect(self.pool.connect, _connection)
  File "/home/airflow/.local/lib/python3.7/site-packages/sqlalchemy/engine/base.py", line 3370, in _wrap_pool_connect
    e, dialect, self
  File "/home/airflow/.local/lib/python3.7/site-packages/sqlalchemy/engine/base.py", line 2204, in _handle_dbapi_exception_noconnection
    sqlalchemy_exception, with_traceback=exc_info[2], from_=e
  File "/home/airflow/.local/lib/python3.7/site-packages/sqlalchemy/util/compat.py", line 211, in raise_
    raise exception
  File "/home/airflow/.local/lib/python3.7/site-packages/sqlalchemy/engine/base.py", line 3366, in _wrap_pool_connect
    return fn()
  File "/home/airflow/.local/lib/python3.7/site-packages/sqlalchemy/pool/base.py", line 327, in connect
    return _ConnectionFairy._checkout(self)
  File "/home/airflow/.local/lib/python3.7/site-packages/sqlalchemy/pool/base.py", line 894, in _checkout
    fairy = _ConnectionRecord.checkout(pool)
  File "/home/airflow/.local/lib/python3.7/site-packages/sqlalchemy/pool/base.py", line 493, in checkout
    rec = pool._do_get()
  File "/home/airflow/.local/lib/python3.7/site-packages/sqlalchemy/pool/impl.py", line 256, in _do_get
    return self._create_connection()
  File "/home/airflow/.local/lib/python3.7/site-packages/sqlalchemy/pool/base.py", line 273, in _create_connection
    return _ConnectionRecord(self)
  File "/home/airflow/.local/lib/python3.7/site-packages/sqlalchemy/pool/base.py", line 388, in __init__
    self.__connect()
  File "/home/airflow/.local/lib/python3.7/site-packages/sqlalchemy/pool/base.py", line 691, in __connect
    pool.logger.debug("Error on connect(): %s", e)
  File "/home/airflow/.local/lib/python3.7/site-packages/sqlalchemy/util/langhelpers.py", line 72, in __exit__
    with_traceback=exc_tb,
  File "/home/airflow/.local/lib/python3.7/site-packages/sqlalchemy/util/compat.py", line 211, in raise_
    raise exception
  File "/home/airflow/.local/lib/python3.7/site-packages/sqlalchemy/pool/base.py", line 686, in __connect
    self.dbapi_connection = connection = pool._invoke_creator(self)
  File "/home/airflow/.local/lib/python3.7/site-packages/sqlalchemy/engine/create.py", line 574, in connect
    return dialect.connect(*cargs, **cparams)
  File "/home/airflow/.local/lib/python3.7/site-packages/sqlalchemy/engine/default.py", line 598, in connect
    return self.dbapi.connect(*cargs, **cparams)
  File "/home/airflow/.local/lib/python3.7/site-packages/psycopg2/__init__.py", line 122, in connect
    conn = _connect(dsn, connection_factory=connection_factory, **kwasync)
sqlalchemy.exc.OperationalError: (psycopg2.OperationalError) could not translate host name "postgres" to address: Temporary failure in name resolution

(Background on this error at: https://sqlalche.me/e/14/e3q8)
[2023-05-23T10:14:10.972+0000] {local_task_job_runner.py:202} ERROR - Heartbeat time limit exceeded!
[2023-05-23T10:14:19.868+0000] {process_utils.py:135} INFO - Sending Signals.SIGTERM to group 704. PIDs of all processes in the group: [704]
[2023-05-23T10:14:19.868+0000] {process_utils.py:86} INFO - Sending the signal Signals.SIGTERM to group 704
[2023-05-23T10:14:22.649+0000] {taskinstance.py:1517} ERROR - Received SIGTERM. Terminating subprocesses.
[2023-05-23T10:14:22.788+0000] {logging_mixin.py:149} WARNING - --- Logging error ---
[2023-05-23T10:14:23.392+0000] {logging_mixin.py:149} WARNING - Traceback (most recent call last):
[2023-05-23T10:14:23.398+0000] {logging_mixin.py:149} WARNING -   File "/home/***/.local/lib/python3.7/site-packages/sqlalchemy/engine/base.py", line 3366, in _wrap_pool_connect
    return fn()
[2023-05-23T10:14:23.398+0000] {logging_mixin.py:149} WARNING -   File "/home/***/.local/lib/python3.7/site-packages/sqlalchemy/pool/base.py", line 327, in connect
    return _ConnectionFairy._checkout(self)
[2023-05-23T10:14:23.398+0000] {logging_mixin.py:149} WARNING -   File "/home/***/.local/lib/python3.7/site-packages/sqlalchemy/pool/base.py", line 894, in _checkout
    fairy = _ConnectionRecord.checkout(pool)
[2023-05-23T10:14:23.399+0000] {logging_mixin.py:149} WARNING -   File "/home/***/.local/lib/python3.7/site-packages/sqlalchemy/pool/base.py", line 493, in checkout
    rec = pool._do_get()
[2023-05-23T10:14:23.399+0000] {logging_mixin.py:149} WARNING -   File "/home/***/.local/lib/python3.7/site-packages/sqlalchemy/pool/impl.py", line 256, in _do_get
    return self._create_connection()
[2023-05-23T10:14:23.400+0000] {logging_mixin.py:149} WARNING -   File "/home/***/.local/lib/python3.7/site-packages/sqlalchemy/pool/base.py", line 273, in _create_connection
    return _ConnectionRecord(self)
[2023-05-23T10:14:23.400+0000] {logging_mixin.py:149} WARNING -   File "/home/***/.local/lib/python3.7/site-packages/sqlalchemy/pool/base.py", line 388, in __init__
    self.__connect()
[2023-05-23T10:14:23.400+0000] {logging_mixin.py:149} WARNING -   File "/home/***/.local/lib/python3.7/site-packages/sqlalchemy/pool/base.py", line 691, in __connect
    pool.logger.debug("Error on connect(): %s", e)
[2023-05-23T10:14:23.400+0000] {logging_mixin.py:149} WARNING -   File "/home/***/.local/lib/python3.7/site-packages/sqlalchemy/util/langhelpers.py", line 72, in __exit__
    with_traceback=exc_tb,
[2023-05-23T10:14:23.402+0000] {logging_mixin.py:149} WARNING -   File "/home/***/.local/lib/python3.7/site-packages/sqlalchemy/util/compat.py", line 211, in raise_
    raise exception
[2023-05-23T10:14:23.404+0000] {logging_mixin.py:149} WARNING -   File "/home/***/.local/lib/python3.7/site-packages/sqlalchemy/pool/base.py", line 686, in __connect
    self.dbapi_connection = connection = pool._invoke_creator(self)
[2023-05-23T10:14:23.406+0000] {logging_mixin.py:149} WARNING -   File "/home/***/.local/lib/python3.7/site-packages/sqlalchemy/engine/create.py", line 574, in connect
    return dialect.connect(*cargs, **cparams)
[2023-05-23T10:14:23.408+0000] {logging_mixin.py:149} WARNING -   File "/home/***/.local/lib/python3.7/site-packages/sqlalchemy/engine/default.py", line 598, in connect
    return self.dbapi.connect(*cargs, **cparams)
[2023-05-23T10:14:23.410+0000] {logging_mixin.py:149} WARNING -   File "/home/***/.local/lib/python3.7/site-packages/psycopg2/__init__.py", line 122, in connect
    conn = _connect(dsn, connection_factory=connection_factory, **kwasync)
[2023-05-23T10:14:23.412+0000] {logging_mixin.py:149} WARNING - psycopg2.OperationalError: could not translate host name "postgres" to address: Temporary failure in name resolution
[2023-05-23T10:14:23.412+0000] {logging_mixin.py:149} WARNING - 
The above exception was the direct cause of the following exception:
[2023-05-23T10:14:23.418+0000] {logging_mixin.py:149} WARNING - Traceback (most recent call last):
[2023-05-23T10:14:23.420+0000] {logging_mixin.py:149} WARNING -   File "/home/***/.local/lib/python3.7/site-packages/***/models/taskinstance.py", line 1407, in _run_raw_task
    self._execute_task_with_callbacks(context, test_mode)
[2023-05-23T10:14:23.421+0000] {logging_mixin.py:149} WARNING -   File "/home/***/.local/lib/python3.7/site-packages/***/models/taskinstance.py", line 1535, in _execute_task_with_callbacks
    RenderedTaskInstanceFields.delete_old_records(self.task_id, self.dag_id)
[2023-05-23T10:14:23.421+0000] {logging_mixin.py:149} WARNING -   File "/home/***/.local/lib/python3.7/site-packages/***/utils/session.py", line 76, in wrapper
    return func(*args, session=session, **kwargs)
[2023-05-23T10:14:23.421+0000] {logging_mixin.py:149} WARNING -   File "/home/***/.local/lib/python3.7/site-packages/***/models/renderedtifields.py", line 223, in delete_old_records
    session=session,
[2023-05-23T10:14:23.422+0000] {logging_mixin.py:149} WARNING -   File "/home/***/.local/lib/python3.7/site-packages/***/utils/retries.py", line 78, in wrapped_function
    for attempt in run_with_db_retries(max_retries=retries, logger=logger, **retry_kwargs):
[2023-05-23T10:14:23.422+0000] {logging_mixin.py:149} WARNING -   File "/home/***/.local/lib/python3.7/site-packages/tenacity/__init__.py", line 347, in __iter__
    do = self.iter(retry_state=retry_state)
[2023-05-23T10:14:23.422+0000] {logging_mixin.py:149} WARNING -   File "/home/***/.local/lib/python3.7/site-packages/tenacity/__init__.py", line 325, in iter
    raise retry_exc.reraise()
[2023-05-23T10:14:23.423+0000] {logging_mixin.py:149} WARNING -   File "/home/***/.local/lib/python3.7/site-packages/tenacity/__init__.py", line 158, in reraise
    raise self.last_attempt.result()
[2023-05-23T10:14:23.423+0000] {logging_mixin.py:149} WARNING -   File "/usr/local/lib/python3.7/concurrent/futures/_base.py", line 428, in result
    return self.__get_result()
[2023-05-23T10:14:23.423+0000] {logging_mixin.py:149} WARNING -   File "/usr/local/lib/python3.7/concurrent/futures/_base.py", line 384, in __get_result
    raise self._exception
[2023-05-23T10:14:23.424+0000] {logging_mixin.py:149} WARNING -   File "/home/***/.local/lib/python3.7/site-packages/***/utils/retries.py", line 87, in wrapped_function
    return func(*args, **kwargs)
[2023-05-23T10:14:23.424+0000] {logging_mixin.py:149} WARNING -   File "/home/***/.local/lib/python3.7/site-packages/***/models/renderedtifields.py", line 245, in _do_delete_old_records
    ).delete(synchronize_session=False)
[2023-05-23T10:14:23.424+0000] {logging_mixin.py:149} WARNING -   File "/home/***/.local/lib/python3.7/site-packages/sqlalchemy/orm/query.py", line 3225, in delete
    execution_options={"synchronize_session": synchronize_session},
[2023-05-23T10:14:23.424+0000] {logging_mixin.py:149} WARNING -   File "/home/***/.local/lib/python3.7/site-packages/sqlalchemy/orm/session.py", line 1716, in execute
    conn = self._connection_for_bind(bind)
[2023-05-23T10:14:23.425+0000] {logging_mixin.py:149} WARNING -   File "/home/***/.local/lib/python3.7/site-packages/sqlalchemy/orm/session.py", line 1556, in _connection_for_bind
    engine, execution_options
[2023-05-23T10:14:23.425+0000] {logging_mixin.py:149} WARNING -   File "/home/***/.local/lib/python3.7/site-packages/sqlalchemy/orm/session.py", line 750, in _connection_for_bind
    conn = bind.connect()
[2023-05-23T10:14:23.425+0000] {logging_mixin.py:149} WARNING -   File "/home/***/.local/lib/python3.7/site-packages/sqlalchemy/engine/base.py", line 3320, in connect
    return self._connection_cls(self, close_with_result=close_with_result)
[2023-05-23T10:14:23.425+0000] {logging_mixin.py:149} WARNING -   File "/home/***/.local/lib/python3.7/site-packages/sqlalchemy/engine/base.py", line 96, in __init__
    else engine.raw_connection()
[2023-05-23T10:14:23.425+0000] {logging_mixin.py:149} WARNING -   File "/home/***/.local/lib/python3.7/site-packages/sqlalchemy/engine/base.py", line 3399, in raw_connection
    return self._wrap_pool_connect(self.pool.connect, _connection)
[2023-05-23T10:14:23.426+0000] {logging_mixin.py:149} WARNING -   File "/home/***/.local/lib/python3.7/site-packages/sqlalchemy/engine/base.py", line 3370, in _wrap_pool_connect
    e, dialect, self
[2023-05-23T10:14:23.426+0000] {logging_mixin.py:149} WARNING -   File "/home/***/.local/lib/python3.7/site-packages/sqlalchemy/engine/base.py", line 2204, in _handle_dbapi_exception_noconnection
    sqlalchemy_exception, with_traceback=exc_info[2], from_=e
[2023-05-23T10:14:23.426+0000] {logging_mixin.py:149} WARNING -   File "/home/***/.local/lib/python3.7/site-packages/sqlalchemy/util/compat.py", line 211, in raise_
    raise exception
[2023-05-23T10:14:23.426+0000] {logging_mixin.py:149} WARNING -   File "/home/***/.local/lib/python3.7/site-packages/sqlalchemy/engine/base.py", line 3366, in _wrap_pool_connect
    return fn()
[2023-05-23T10:14:23.426+0000] {logging_mixin.py:149} WARNING -   File "/home/***/.local/lib/python3.7/site-packages/sqlalchemy/pool/base.py", line 327, in connect
    return _ConnectionFairy._checkout(self)
[2023-05-23T10:14:23.427+0000] {logging_mixin.py:149} WARNING -   File "/home/***/.local/lib/python3.7/site-packages/sqlalchemy/pool/base.py", line 894, in _checkout
    fairy = _ConnectionRecord.checkout(pool)
[2023-05-23T10:14:23.427+0000] {logging_mixin.py:149} WARNING -   File "/home/***/.local/lib/python3.7/site-packages/sqlalchemy/pool/base.py", line 493, in checkout
    rec = pool._do_get()
[2023-05-23T10:14:23.427+0000] {logging_mixin.py:149} WARNING -   File "/home/***/.local/lib/python3.7/site-packages/sqlalchemy/pool/impl.py", line 256, in _do_get
    return self._create_connection()
[2023-05-23T10:14:23.427+0000] {logging_mixin.py:149} WARNING -   File "/home/***/.local/lib/python3.7/site-packages/sqlalchemy/pool/base.py", line 273, in _create_connection
    return _ConnectionRecord(self)
[2023-05-23T10:14:23.428+0000] {logging_mixin.py:149} WARNING -   File "/home/***/.local/lib/python3.7/site-packages/sqlalchemy/pool/base.py", line 388, in __init__
    self.__connect()
[2023-05-23T10:14:23.428+0000] {logging_mixin.py:149} WARNING -   File "/home/***/.local/lib/python3.7/site-packages/sqlalchemy/pool/base.py", line 691, in __connect
    pool.logger.debug("Error on connect(): %s", e)
[2023-05-23T10:14:23.428+0000] {logging_mixin.py:149} WARNING -   File "/home/***/.local/lib/python3.7/site-packages/sqlalchemy/util/langhelpers.py", line 72, in __exit__
    with_traceback=exc_tb,
[2023-05-23T10:14:23.428+0000] {logging_mixin.py:149} WARNING -   File "/home/***/.local/lib/python3.7/site-packages/sqlalchemy/util/compat.py", line 211, in raise_
    raise exception
[2023-05-23T10:14:23.429+0000] {logging_mixin.py:149} WARNING -   File "/home/***/.local/lib/python3.7/site-packages/sqlalchemy/pool/base.py", line 686, in __connect
    self.dbapi_connection = connection = pool._invoke_creator(self)
[2023-05-23T10:14:23.429+0000] {logging_mixin.py:149} WARNING -   File "/home/***/.local/lib/python3.7/site-packages/sqlalchemy/engine/create.py", line 574, in connect
    return dialect.connect(*cargs, **cparams)
[2023-05-23T10:14:23.429+0000] {logging_mixin.py:149} WARNING -   File "/home/***/.local/lib/python3.7/site-packages/sqlalchemy/engine/default.py", line 598, in connect
    return self.dbapi.connect(*cargs, **cparams)
[2023-05-23T10:14:23.429+0000] {logging_mixin.py:149} WARNING -   File "/home/***/.local/lib/python3.7/site-packages/psycopg2/__init__.py", line 122, in connect
    conn = _connect(dsn, connection_factory=connection_factory, **kwasync)
[2023-05-23T10:14:23.429+0000] {logging_mixin.py:149} WARNING - sqlalchemy.exc.OperationalError: (psycopg2.OperationalError) could not translate host name "postgres" to address: Temporary failure in name resolution

(Background on this error at: https://sqlalche.me/e/14/e3q8)
[2023-05-23T10:14:23.430+0000] {logging_mixin.py:149} WARNING - 
During handling of the above exception, another exception occurred:
[2023-05-23T10:14:23.430+0000] {logging_mixin.py:149} WARNING - Traceback (most recent call last):
[2023-05-23T10:14:23.430+0000] {logging_mixin.py:149} WARNING -   File "/usr/local/lib/python3.7/logging/__init__.py", line 1025, in emit
    msg = self.format(record)
[2023-05-23T10:14:23.430+0000] {logging_mixin.py:149} WARNING -   File "/usr/local/lib/python3.7/logging/__init__.py", line 869, in format
    return fmt.format(record)
[2023-05-23T10:14:23.431+0000] {logging_mixin.py:149} WARNING -   File "/usr/local/lib/python3.7/logging/__init__.py", line 616, in format
    record.exc_text = self.formatException(record.exc_info)
[2023-05-23T10:14:23.431+0000] {logging_mixin.py:149} WARNING -   File "/usr/local/lib/python3.7/logging/__init__.py", line 566, in formatException
    traceback.print_exception(ei[0], ei[1], tb, None, sio)
[2023-05-23T10:14:23.431+0000] {logging_mixin.py:149} WARNING -   File "/usr/local/lib/python3.7/traceback.py", line 104, in print_exception
    type(value), value, tb, limit=limit).format(chain=chain):
[2023-05-23T10:14:23.431+0000] {logging_mixin.py:149} WARNING -   File "/home/***/.local/lib/python3.7/site-packages/exceptiongroup/_formatting.py", line 100, in __init__
    capture_locals=capture_locals,
[2023-05-23T10:14:23.431+0000] {logging_mixin.py:149} WARNING -   File "/usr/local/lib/python3.7/traceback.py", line 357, in extract
    filename, lineno, name, lookup_line=False, locals=f_locals))
[2023-05-23T10:14:23.432+0000] {logging_mixin.py:149} WARNING -   File "/usr/local/lib/python3.7/traceback.py", line 243, in __init__
    def __init__(self, filename, lineno, name, *, lookup_line=True,
[2023-05-23T10:14:23.432+0000] {logging_mixin.py:149} WARNING -   File "/home/***/.local/lib/python3.7/site-packages/***/models/taskinstance.py", line 1519, in signal_handler
    raise AirflowException("Task received SIGTERM signal")
[2023-05-23T10:14:23.432+0000] {logging_mixin.py:149} WARNING - ***.exceptions.AirflowException: Task received SIGTERM signal
[2023-05-23T10:14:23.432+0000] {logging_mixin.py:149} WARNING - Call stack:
[2023-05-23T10:14:23.895+0000] {logging_mixin.py:149} WARNING -   File "/home/***/.local/bin/***", line 8, in <module>
    sys.exit(main())
[2023-05-23T10:14:23.903+0000] {logging_mixin.py:149} WARNING -   File "/home/***/.local/lib/python3.7/site-packages/***/__main__.py", line 48, in main
    args.func(args)
[2023-05-23T10:14:23.903+0000] {logging_mixin.py:149} WARNING -   File "/home/***/.local/lib/python3.7/site-packages/***/cli/cli_config.py", line 51, in command
    return func(*args, **kwargs)
[2023-05-23T10:14:23.908+0000] {logging_mixin.py:149} WARNING -   File "/home/***/.local/lib/python3.7/site-packages/***/utils/cli.py", line 112, in wrapper
    return f(*args, **kwargs)
[2023-05-23T10:14:23.908+0000] {logging_mixin.py:149} WARNING -   File "/home/***/.local/lib/python3.7/site-packages/***/cli/commands/scheduler_command.py", line 77, in scheduler
    _run_scheduler_job(job_runner, skip_serve_logs=args.skip_serve_logs)
[2023-05-23T10:14:23.909+0000] {logging_mixin.py:149} WARNING -   File "/home/***/.local/lib/python3.7/site-packages/***/cli/commands/scheduler_command.py", line 42, in _run_scheduler_job
    run_job(job=job_runner.job, execute_callable=job_runner._execute)
[2023-05-23T10:14:23.909+0000] {logging_mixin.py:149} WARNING -   File "/home/***/.local/lib/python3.7/site-packages/***/utils/session.py", line 76, in wrapper
    return func(*args, session=session, **kwargs)
[2023-05-23T10:14:23.909+0000] {logging_mixin.py:149} WARNING -   File "/home/***/.local/lib/python3.7/site-packages/***/jobs/job.py", line 284, in run_job
    return execute_job(job, execute_callable=execute_callable)
[2023-05-23T10:14:23.909+0000] {logging_mixin.py:149} WARNING -   File "/home/***/.local/lib/python3.7/site-packages/***/jobs/job.py", line 313, in execute_job
    ret = execute_callable()
[2023-05-23T10:14:23.909+0000] {logging_mixin.py:149} WARNING -   File "/home/***/.local/lib/python3.7/site-packages/***/jobs/scheduler_job_runner.py", line 833, in _execute
    self.job.executor.start()
[2023-05-23T10:14:23.910+0000] {logging_mixin.py:149} WARNING -   File "/home/***/.local/lib/python3.7/site-packages/***/executors/local_executor.py", line 367, in start
    self.impl.start()
[2023-05-23T10:14:23.910+0000] {logging_mixin.py:149} WARNING -   File "/home/***/.local/lib/python3.7/site-packages/***/executors/local_executor.py", line 308, in start
    worker.start()
[2023-05-23T10:14:23.910+0000] {logging_mixin.py:149} WARNING -   File "/usr/local/lib/python3.7/multiprocessing/process.py", line 112, in start
    self._popen = self._Popen(self)
[2023-05-23T10:14:23.910+0000] {logging_mixin.py:149} WARNING -   File "/usr/local/lib/python3.7/multiprocessing/context.py", line 223, in _Popen
    return _default_context.get_context().Process._Popen(process_obj)
[2023-05-23T10:14:23.910+0000] {logging_mixin.py:149} WARNING -   File "/usr/local/lib/python3.7/multiprocessing/context.py", line 277, in _Popen
    return Popen(process_obj)
[2023-05-23T10:14:23.911+0000] {logging_mixin.py:149} WARNING -   File "/usr/local/lib/python3.7/multiprocessing/popen_fork.py", line 20, in __init__
    self._launch(process_obj)
[2023-05-23T10:14:23.911+0000] {logging_mixin.py:149} WARNING -   File "/usr/local/lib/python3.7/multiprocessing/popen_fork.py", line 74, in _launch
    code = process_obj._bootstrap()
[2023-05-23T10:14:23.911+0000] {logging_mixin.py:149} WARNING -   File "/usr/local/lib/python3.7/multiprocessing/process.py", line 297, in _bootstrap
    self.run()
[2023-05-23T10:14:23.911+0000] {logging_mixin.py:149} WARNING -   File "/home/***/.local/lib/python3.7/site-packages/***/executors/local_executor.py", line 74, in run
    return super().run()
[2023-05-23T10:14:23.911+0000] {logging_mixin.py:149} WARNING -   File "/usr/local/lib/python3.7/multiprocessing/process.py", line 99, in run
    self._target(*self._args, **self._kwargs)
[2023-05-23T10:14:23.928+0000] {logging_mixin.py:149} WARNING -   File "/home/***/.local/lib/python3.7/site-packages/***/executors/local_executor.py", line 198, in do_work
    self.execute_work(key=key, command=command)
[2023-05-23T10:14:23.928+0000] {logging_mixin.py:149} WARNING -   File "/home/***/.local/lib/python3.7/site-packages/***/executors/local_executor.py", line 91, in execute_work
    state = self._execute_work_in_fork(command)
[2023-05-23T10:14:23.928+0000] {logging_mixin.py:149} WARNING -   File "/home/***/.local/lib/python3.7/site-packages/***/executors/local_executor.py", line 131, in _execute_work_in_fork
    args.func(args)
[2023-05-23T10:14:23.928+0000] {logging_mixin.py:149} WARNING -   File "/home/***/.local/lib/python3.7/site-packages/***/cli/cli_config.py", line 51, in command
    return func(*args, **kwargs)
[2023-05-23T10:14:23.928+0000] {logging_mixin.py:149} WARNING -   File "/home/***/.local/lib/python3.7/site-packages/***/utils/cli.py", line 112, in wrapper
    return f(*args, **kwargs)
[2023-05-23T10:14:23.929+0000] {logging_mixin.py:149} WARNING -   File "/home/***/.local/lib/python3.7/site-packages/***/cli/commands/task_command.py", line 425, in task_run
    task_return_code = _run_task_by_selected_method(args, _dag, ti)
[2023-05-23T10:14:23.929+0000] {logging_mixin.py:149} WARNING -   File "/home/***/.local/lib/python3.7/site-packages/***/cli/commands/task_command.py", line 203, in _run_task_by_selected_method
    return _run_task_by_local_task_job(args, ti)
[2023-05-23T10:14:23.929+0000] {logging_mixin.py:149} WARNING -   File "/home/***/.local/lib/python3.7/site-packages/***/cli/commands/task_command.py", line 265, in _run_task_by_local_task_job
    ret = run_job(job=job_runner.job, execute_callable=job_runner._execute)
[2023-05-23T10:14:23.929+0000] {logging_mixin.py:149} WARNING -   File "/home/***/.local/lib/python3.7/site-packages/***/utils/session.py", line 76, in wrapper
    return func(*args, session=session, **kwargs)
[2023-05-23T10:14:23.929+0000] {logging_mixin.py:149} WARNING -   File "/home/***/.local/lib/python3.7/site-packages/***/jobs/job.py", line 284, in run_job
    return execute_job(job, execute_callable=execute_callable)
[2023-05-23T10:14:23.929+0000] {logging_mixin.py:149} WARNING -   File "/home/***/.local/lib/python3.7/site-packages/***/jobs/job.py", line 313, in execute_job
    ret = execute_callable()
[2023-05-23T10:14:23.930+0000] {logging_mixin.py:149} WARNING -   File "/home/***/.local/lib/python3.7/site-packages/***/jobs/local_task_job_runner.py", line 159, in _execute
    self.task_runner.start()
[2023-05-23T10:14:23.930+0000] {logging_mixin.py:149} WARNING -   File "/home/***/.local/lib/python3.7/site-packages/***/task/task_runner/standard_task_runner.py", line 45, in start
    self.process = self._start_by_fork()
[2023-05-23T10:14:23.930+0000] {logging_mixin.py:149} WARNING -   File "/home/***/.local/lib/python3.7/site-packages/***/task/task_runner/standard_task_runner.py", line 97, in _start_by_fork
    ret = args.func(args, dag=self.dag)
[2023-05-23T10:14:23.930+0000] {logging_mixin.py:149} WARNING -   File "/home/***/.local/lib/python3.7/site-packages/***/cli/cli_config.py", line 51, in command
    return func(*args, **kwargs)
[2023-05-23T10:14:23.930+0000] {logging_mixin.py:149} WARNING -   File "/home/***/.local/lib/python3.7/site-packages/***/utils/cli.py", line 112, in wrapper
    return f(*args, **kwargs)
[2023-05-23T10:14:23.931+0000] {logging_mixin.py:149} WARNING -   File "/home/***/.local/lib/python3.7/site-packages/***/cli/commands/task_command.py", line 425, in task_run
    task_return_code = _run_task_by_selected_method(args, _dag, ti)
[2023-05-23T10:14:23.931+0000] {logging_mixin.py:149} WARNING -   File "/home/***/.local/lib/python3.7/site-packages/***/cli/commands/task_command.py", line 205, in _run_task_by_selected_method
    return _run_raw_task(args, ti)
[2023-05-23T10:14:23.931+0000] {logging_mixin.py:149} WARNING -   File "/home/***/.local/lib/python3.7/site-packages/***/cli/commands/task_command.py", line 287, in _run_raw_task
    pool=args.pool,
[2023-05-23T10:14:23.931+0000] {logging_mixin.py:149} WARNING -   File "/home/***/.local/lib/python3.7/site-packages/***/utils/session.py", line 76, in wrapper
    return func(*args, session=session, **kwargs)
[2023-05-23T10:14:23.931+0000] {logging_mixin.py:149} WARNING -   File "/home/***/.local/lib/python3.7/site-packages/***/models/taskinstance.py", line 1461, in _run_raw_task
    self.handle_failure(e, test_mode, context, session=session)
[2023-05-23T10:14:23.931+0000] {logging_mixin.py:149} WARNING -   File "/home/***/.local/lib/python3.7/site-packages/***/utils/session.py", line 73, in wrapper
    return func(*args, **kwargs)
[2023-05-23T10:14:23.931+0000] {logging_mixin.py:149} WARNING -   File "/home/***/.local/lib/python3.7/site-packages/***/models/taskinstance.py", line 1824, in handle_failure
    self.log.error("Task failed with exception", exc_info=(type(error), error, tb))
[2023-05-23T10:14:23.932+0000] {logging_mixin.py:149} WARNING -   File "/usr/local/lib/python3.7/logging/__init__.py", line 1407, in error
    self._log(ERROR, msg, args, **kwargs)
[2023-05-23T10:14:23.932+0000] {logging_mixin.py:149} WARNING -   File "/usr/local/lib/python3.7/logging/__init__.py", line 1514, in _log
    self.handle(record)
[2023-05-23T10:14:23.932+0000] {logging_mixin.py:149} WARNING -   File "/usr/local/lib/python3.7/logging/__init__.py", line 1524, in handle
    self.callHandlers(record)
[2023-05-23T10:14:23.932+0000] {logging_mixin.py:149} WARNING -   File "/usr/local/lib/python3.7/logging/__init__.py", line 1586, in callHandlers
    hdlr.handle(record)
[2023-05-23T10:14:23.932+0000] {logging_mixin.py:149} WARNING -   File "/usr/local/lib/python3.7/logging/__init__.py", line 894, in handle
    self.emit(record)
[2023-05-23T10:14:23.933+0000] {logging_mixin.py:149} WARNING -   File "/home/***/.local/lib/python3.7/site-packages/***/utils/log/file_task_handler.py", line 211, in emit
    self.handler.emit(record)
[2023-05-23T10:14:23.933+0000] {logging_mixin.py:149} WARNING - Message: 'Task failed with exception'
Arguments: ()
[2023-05-23T10:14:24.274+0000] {taskinstance.py:1350} INFO - Marking task as UP_FOR_RETRY. dag_id=dag_with_taskflow_api_v02, task_id=get_name, execution_date=20211026T000000, start_date=20230523T100849, end_date=20230523T101424
[2023-05-23T10:14:24.966+0000] {standard_task_runner.py:109} ERROR - Failed to execute job 5 for task get_name ((psycopg2.OperationalError) could not translate host name "postgres" to address: Temporary failure in name resolution

(Background on this error at: https://sqlalche.me/e/14/e3q8); 704)
[2023-05-23T10:14:25.382+0000] {process_utils.py:79} INFO - Process psutil.Process(pid=704, status='terminated', exitcode=1, started='10:08:49') (704) terminated with exit code 1
[2023-05-23T10:26:25.197+0000] {taskinstance.py:1103} INFO - Dependencies all met for dep_context=non-requeueable deps ti=<TaskInstance: dag_with_taskflow_api_v02.get_name scheduled__2021-10-26T00:00:00+00:00 [queued]>
[2023-05-23T10:26:25.297+0000] {taskinstance.py:1103} INFO - Dependencies all met for dep_context=requeueable deps ti=<TaskInstance: dag_with_taskflow_api_v02.get_name scheduled__2021-10-26T00:00:00+00:00 [queued]>
[2023-05-23T10:26:25.305+0000] {taskinstance.py:1308} INFO - Starting attempt 1 of 6
[2023-05-23T10:26:25.504+0000] {taskinstance.py:1327} INFO - Executing <Task(_PythonDecoratedOperator): get_name> on 2021-10-26 00:00:00+00:00
[2023-05-23T10:26:25.518+0000] {standard_task_runner.py:57} INFO - Started process 209 to run task
[2023-05-23T10:26:25.617+0000] {standard_task_runner.py:84} INFO - Running: ['***', 'tasks', 'run', 'dag_with_taskflow_api_v02', 'get_name', 'scheduled__2021-10-26T00:00:00+00:00', '--job-id', '16', '--raw', '--subdir', 'DAGS_FOLDER/first_dag.py', '--cfg-path', '/tmp/tmpoe4z5ppm']
[2023-05-23T10:26:25.687+0000] {standard_task_runner.py:85} INFO - Job 16: Subtask get_name
[2023-05-23T10:26:26.993+0000] {task_command.py:410} INFO - Running <TaskInstance: dag_with_taskflow_api_v02.get_name scheduled__2021-10-26T00:00:00+00:00 [running]> on host 8a6612510f4c
[2023-05-23T10:26:28.586+0000] {taskinstance.py:1547} INFO - Exporting env vars: AIRFLOW_CTX_DAG_OWNER='coder2j' AIRFLOW_CTX_DAG_ID='dag_with_taskflow_api_v02' AIRFLOW_CTX_TASK_ID='get_name' AIRFLOW_CTX_EXECUTION_DATE='2021-10-26T00:00:00+00:00' AIRFLOW_CTX_TRY_NUMBER='1' AIRFLOW_CTX_DAG_RUN_ID='scheduled__2021-10-26T00:00:00+00:00'
[2023-05-23T10:26:28.593+0000] {python.py:183} INFO - Done. Returned value was: {'first_name': 'Jerry', 'last_name': 'Fridman'}
[2023-05-23T10:26:28.889+0000] {taskinstance.py:1350} INFO - Marking task as SUCCESS. dag_id=dag_with_taskflow_api_v02, task_id=get_name, execution_date=20211026T000000, start_date=20230523T102625, end_date=20230523T102628
[2023-05-23T10:26:29.106+0000] {local_task_job_runner.py:225} INFO - Task exited with return code 0
[2023-05-23T10:26:29.504+0000] {taskinstance.py:2651} INFO - 0 downstream tasks scheduled from follow-on schedule check
