[2023-05-23T10:29:47.066+0000] {taskinstance.py:1103} INFO - Dependencies all met for dep_context=non-requeueable deps ti=<TaskInstance: dag_with_taskflow_api_v02.get_name scheduled__2022-01-09T00:00:00+00:00 [queued]>
[2023-05-23T10:29:47.229+0000] {taskinstance.py:1103} INFO - Dependencies all met for dep_context=requeueable deps ti=<TaskInstance: dag_with_taskflow_api_v02.get_name scheduled__2022-01-09T00:00:00+00:00 [queued]>
[2023-05-23T10:29:47.243+0000] {taskinstance.py:1308} INFO - Starting attempt 1 of 6
[2023-05-23T10:29:47.614+0000] {taskinstance.py:1327} INFO - Executing <Task(_PythonDecoratedOperator): get_name> on 2022-01-09 00:00:00+00:00
[2023-05-23T10:29:47.669+0000] {standard_task_runner.py:57} INFO - Started process 717 to run task
[2023-05-23T10:29:47.791+0000] {standard_task_runner.py:84} INFO - Running: ['***', 'tasks', 'run', 'dag_with_taskflow_api_v02', 'get_name', 'scheduled__2022-01-09T00:00:00+00:00', '--job-id', '226', '--raw', '--subdir', 'DAGS_FOLDER/first_dag.py', '--cfg-path', '/tmp/tmpomreuvkr']
[2023-05-23T10:29:47.839+0000] {standard_task_runner.py:85} INFO - Job 226: Subtask get_name
[2023-05-23T10:29:48.496+0000] {task_command.py:410} INFO - Running <TaskInstance: dag_with_taskflow_api_v02.get_name scheduled__2022-01-09T00:00:00+00:00 [running]> on host 8a6612510f4c
[2023-05-23T10:29:49.793+0000] {taskinstance.py:1547} INFO - Exporting env vars: AIRFLOW_CTX_DAG_OWNER='Sai' AIRFLOW_CTX_DAG_ID='dag_with_taskflow_api_v02' AIRFLOW_CTX_TASK_ID='get_name' AIRFLOW_CTX_EXECUTION_DATE='2022-01-09T00:00:00+00:00' AIRFLOW_CTX_TRY_NUMBER='1' AIRFLOW_CTX_DAG_RUN_ID='scheduled__2022-01-09T00:00:00+00:00'
[2023-05-23T10:29:49.802+0000] {python.py:183} INFO - Done. Returned value was: {'first_name': 'Sai', 'last_name': 'Tr'}
[2023-05-23T10:29:50.191+0000] {local_task_job_runner.py:115} ERROR - Received SIGTERM. Terminating subprocesses
[2023-05-23T10:29:50.423+0000] {process_utils.py:135} INFO - Sending Signals.SIGTERM to group 717. PIDs of all processes in the group: [717]
[2023-05-23T10:29:50.423+0000] {process_utils.py:86} INFO - Sending the signal Signals.SIGTERM to group 717
[2023-05-23T10:29:50.471+0000] {taskinstance.py:1517} ERROR - Received SIGTERM. Terminating subprocesses.
[2023-05-23T10:29:51.459+0000] {taskinstance.py:1824} ERROR - Task failed with exception
Traceback (most recent call last):
  File "/home/airflow/.local/lib/python3.7/site-packages/airflow/utils/session.py", line 73, in wrapper
    return func(*args, **kwargs)
  File "/home/airflow/.local/lib/python3.7/site-packages/airflow/models/taskinstance.py", line 2361, in xcom_push
    session=session,
  File "/home/airflow/.local/lib/python3.7/site-packages/airflow/utils/session.py", line 73, in wrapper
    return func(*args, **kwargs)
  File "/home/airflow/.local/lib/python3.7/site-packages/airflow/models/xcom.py", line 252, in set
    cls.map_index == map_index,
  File "/home/airflow/.local/lib/python3.7/site-packages/sqlalchemy/orm/query.py", line 3225, in delete
    execution_options={"synchronize_session": synchronize_session},
  File "/home/airflow/.local/lib/python3.7/site-packages/sqlalchemy/orm/session.py", line 1717, in execute
    result = conn._execute_20(statement, params or {}, execution_options)
  File "/home/airflow/.local/lib/python3.7/site-packages/sqlalchemy/engine/base.py", line 1710, in _execute_20
    return meth(self, args_10style, kwargs_10style, execution_options)
  File "/home/airflow/.local/lib/python3.7/site-packages/sqlalchemy/sql/elements.py", line 335, in _execute_on_connection
    self, multiparams, params, execution_options
  File "/home/airflow/.local/lib/python3.7/site-packages/sqlalchemy/engine/base.py", line 1587, in _execute_clauseelement
    cache_hit=cache_hit,
  File "/home/airflow/.local/lib/python3.7/site-packages/sqlalchemy/engine/base.py", line 1949, in _execute_context
    e, statement, parameters, cursor, context
  File "/home/airflow/.local/lib/python3.7/site-packages/sqlalchemy/engine/base.py", line 2133, in _handle_dbapi_exception
    util.raise_(exc_info[1], with_traceback=exc_info[2])
  File "/home/airflow/.local/lib/python3.7/site-packages/sqlalchemy/util/compat.py", line 211, in raise_
    raise exception
  File "/home/airflow/.local/lib/python3.7/site-packages/sqlalchemy/engine/base.py", line 1906, in _execute_context
    cursor, statement, parameters, context
  File "/home/airflow/.local/lib/python3.7/site-packages/sqlalchemy/engine/default.py", line 736, in do_execute
    cursor.execute(statement, parameters)
  File "/usr/local/lib/python3.7/encodings/utf_8.py", line 15, in decode
    def decode(input, errors='strict'):
  File "/home/airflow/.local/lib/python3.7/site-packages/airflow/models/taskinstance.py", line 1519, in signal_handler
    raise AirflowException("Task received SIGTERM signal")
airflow.exceptions.AirflowException: Task received SIGTERM signal
[2023-05-23T10:29:51.557+0000] {taskinstance.py:1350} INFO - Marking task as UP_FOR_RETRY. dag_id=dag_with_taskflow_api_v02, task_id=get_name, execution_date=20220109T000000, start_date=20230523T102947, end_date=20230523T102951
[2023-05-23T10:29:51.742+0000] {standard_task_runner.py:109} ERROR - Failed to execute job 226 for task get_name (Task received SIGTERM signal; 717)
[2023-05-23T10:29:51.871+0000] {process_utils.py:79} INFO - Process psutil.Process(pid=717, status='terminated', exitcode=1, started='10:29:47') (717) terminated with exit code 1
[2023-05-23T10:29:51.873+0000] {local_task_job_runner.py:225} INFO - Task exited with return code 143
[2023-05-23T10:29:52.031+0000] {taskinstance.py:2651} INFO - 0 downstream tasks scheduled from follow-on schedule check
